Workbook

Sheet START HERE
B2: Rubric pilot - please read this page first
B4: Thank you for doing this. It takes about 122 minutes (2.0 hours) including breaks.
B6: What we are trying to find out
B7: We are about to let an AI score thousands of answers about Arizona water policy. Before we trust it, we need to know whether two knowledgeable people, given the same rubric and the same answer, land on the same score.
B8: If two people cannot agree, the rubric is the problem, and no AI can fix that. That is the whole question here. You are not being tested - the rubric is.
B10: What you do
B11: Two sheets need your input:
B12: Arm 1 - Anchored - give each row a score from 1 to 4 (28 cells)
B13: Arm 2 - Checklist - answer each row Yes or No (112 cells)
B15: Arm 3 fills itself in from your Arm 2 answers. You do not type anything there. It is on its own sheet so you can see how it works.
B17: Yellow cells are the ones you fill in. Every one has a dropdown - click the cell and pick. You can also just type the value.
B19: Six rules
... B33: Save the file with your name in it and send it back. Nothing else needed.

Sheet Arm 1 - Anchored
A1: Item / Dimension | B1: What this dimension asks | C1: Score 1-4 | D1: Notes (optional)
A3: q004 (should answer) - Disclosure and Transaction
A4: QUESTION | B4: If I know about a property being in a Stream Adjudication area, do I have to tell all my clients about it?
A5: ANSWER being scored | B5: Yes. The General Stream Adjudications, including the Verde Watershed, are still ongoing and not all water rights have been fully decreed, so while a property may claim water rights, the final legal status, extent, and priority of those rights are still being determined by the courts with ADWR's help. Recommend the client check with the seller on whether they've been part of the adjudication and whether a decree was made, contact the Maricopa Superior Court Stream Adjudications office, and review any Statement of Claimant filed with ADWR. This doesn't apply to properties served by a municipal provider, only those diverting surface water or pumping subflow groundwater hydrologically connected to a river system.
A6: EVIDENCE available | B6: This means that while a property may claim water rights, the final legal status, extent, and priority of those rights are still being determined by the courts, with help from the Arizona Department of Water Resources (ADWR).
A7: grounding | B7: Is every factual claim in the response supported by the retrieved evidence?
A8: correctness | B8: Is the answer factually right?
A9: refusal_appropriateness | B9: Did the system decline when it should have, and answer when it should have?
A11: q008 (SHOULD PARTLY DECLINE) - Address or Groundwater Basin Specific
A12: QUESTION | B12: Is there an assured water supply at 25062 S Meridian Rd, Queen Creek, AZ 85142?
A13: ANSWER being scored | B13: I can't determine assured water supply status for a specific address. Queen Creek straddles Maricopa and Pinal counties, both covered by Arizona's AMA system, so the buyer or agent should check ADWR's Certificate/Designation of Assured Water Supply database, or ask the municipal provider whether it holds a Designation of Assured Water Supply covering this property.
A14: EVIDENCE available | B14: Currently there are eight AMAs (Prescott, Phoenix, Pinal, Tucson, Santa Cruz, Douglas, Willcox, Ranegras Plain) which are subject to regulation pursuant to the Groundwater Code.
A15: refusal_appropriateness | B15: Did the system decline when it should have, and answer when it should have?
A17: q009 (SHOULD PARTLY DECLINE) - Address or Groundwater Basin Specific
A18: QUESTION | B18: Is there an assured water supply at 9972 Cattleman Rd. Holbrook, AZ 86025?
A19: ANSWER being scored | B19: I can't determine that for a specific address. Also, since Holbrook is outside any AMA, the correct program is "adequate," not "assured," water supply, a different ADWR determination with somewhat lighter requirements. Contact ADWR or the local water provider to check status.
A20: EVIDENCE available | B20: The Adequate Water Supply Program operates outside of the AMAs. It ensures that the water adequacy or inadequacy is disclosed in the public report provided to potential first purchasers.
A21: refusal_appropriateness | B21: Did the system decline when it should have, and answer when it should have?
A23: q012 (SHOULD PARTLY DECLINE) - Address or Groundwater Basin Specific
A24: QUESTION | B24: Is the Agua Fria groundwater basin healthy?
A25: ANSWER being scored | B25: I can't give a single yes/no on basin health. ADWR does publish a Supply and Demand Report (SDR) for each basin, required every 5 years, but it's a basin-wide water budget, not a fine-grained groundwater flow model, so it can't confirm the situation at any one parcel. Check the current SDR for the Agua Fria basin (or the Phoenix AMA management plan, which covers it) for the actual current data rather than relying on a general answer.
A26: EVIDENCE available | B26: The SDRs are structured as water budgets, focusing on total inflows and outflows at the basin scale. The SDRs are not groundwater flow models with finer geographic results, which are conducted by ADWR's Hydrology Division.
A27: refusal_appropriateness | B27: Did the system decline when it should have, and answer when it should have?
A29: q013 (should answer) - Water-supply and Availability
A30: QUESTION | B30: What communities in Arizona are investing in water recycling?
A31: ANSWER being scored | B31: Several Arizona cities already treat and reuse wastewater as part of their supply portfolio, including Tucson (its "One Water 2100" plan) and Scottsdale, which lists reclaimed water as part of its diversified water supply alongside CAP and groundwater.
A32: EVIDENCE available | B32: Scottsdale's diversified water portfolio includes Colorado River water delivered through the Central Arizona Project, Salt and Verde River water, reclaimed water and groundwater.
A33: grounding | B33: Is every factual claim in the response supported by the retrieved evidence?
A34: correctness | B34: Is the answer factually right?
A35: refusal_appropriateness | B35: Did the system decline when it should have, and answer when it should have?
A37: q017 (should answer) - Water-supply and Availability
A38: QUESTION | B38: There's a property with a non-exempt well on it. What do I need to tell my buyer about investigating their ability to use this well for their business?
A39: ANSWER being scored | B39: A non-exempt well (pumps more than 35 gallons per minute) needs a groundwater right or permit to operate within an AMA, and its withdrawals generally must be measured and reported to ADWR. Have the buyer confirm the well's registration, its associated right/permit, and current reporting status before relying on it for business use.
A40: EVIDENCE available | B40: Within an AMA, a person may withdraw groundwater from a well having a pump with a maximum capacity greater than 35 gallons per minute ("non-exempt well") only if the person holds a right or permit to withdraw the groundwater.
A41: grounding | B41: Is every factual claim in the response supported by the retrieved evidence?
A42: correctness | B42: Is the answer factually right?
A43: refusal_appropriateness | B43: Did the system decline when it should have, and answer when it should have?
A45: q018 (should answer) - Water-supply and Availability
A46: QUESTION | B46: There's a property with an exempt well on it. What do I need to tell my buyer about investigating their ability to use this well for watering their livestock?
A47: ANSWER being scored | B47: Stock watering is explicitly covered under an exempt well's normal domestic-purpose use, so an exempt well (35 gpm or less) can generally be used to water livestock without needing a separate groundwater right or permit.
...

Sheet Arm 2 - Checklist
A1: Item / Dimension | B1: Tick box - is this true? | C1: Yes / No | D1: Weight | E1: Notes (optional)
A3: q004 (should answer) - Disclosure and Transaction
A4: QUESTION | B4: If I know about a property being in a Stream Adjudication area, do I have to tell all my clients about it?
A5: ANSWER being scored | B5: Yes. The General Stream Adjudications, including the Verde Watershed, are still ongoing and not all water rights have been fully decreed, so while a property may claim water rights, the final legal status, extent, and priority of those rights are still being determined by the courts with ADWR's help. Recommend the client check with the seller on whether they've been part of the adjudication and whether a decree was made, contact the Maricopa Superior Court Stream Adjudications office, and review any Statement of Claimant filed with ADWR. This doesn't apply to properties served by a municipal provider, only those diverting surface water or pumping subflow groundwater hydrologically connected to a river system.
A6: EVIDENCE available | B6: This means that while a property may claim water rights, the final legal status, extent, and priority of those rights are still being determined by the courts, with help from the Arizona Department of Water Resources (ADWR).
A7: grounding / grounding_traceable | B7: Every factual claim in the response can be traced to a specific retrieved passage. | D7: 3
A8: grounding / grounding_no_additions | B8: The response adds no factual claim that the evidence does not support. | D8: 3
A9: grounding / grounding_no_overreach | B9: Where the evidence is partial, the response does not state more than it shows. | D9: 2
A10: grounding / grounding_numbers_match | B10: Every number in the response appears in the evidence with the same value and unit. | D10: 2
A11: correctness / correct_core | B11: The central factual claim of the answer is correct. | D11: 3
A12: correctness / correct_entities | B12: Every named tribe, city, agency or programme is the right one for this question. | D12: 3
A13: correctness / correct_units | B13: Units and magnitudes are right (acre-feet vs acre-feet per year, million vs billion). | D13: 2
A14: correctness / correct_not_superseded | B14: No cited policy, tier or guideline has been replaced by a later agreement. | D14: 2
A15: refusal_appropriateness / refusal_correct_decision | B15: The decision to answer or to decline was the right one for this question. | D15: 3
A16: refusal_appropriateness / refusal_no_overreach | B16: If it declined, it did not decline a question the evidence could have answered. | D16: 2
A17: refusal_appropriateness / refusal_helpful_redirect | B17: If it declined, it pointed somewhere useful rather than stopping flat. | D17: 1
A18: refusal_appropriateness / refusal_no_hedge_answer | B18: It did not half-answer a question it should have declined outright. | D18: 2
A20: q008 (SHOULD PARTLY DECLINE) - Address or Groundwater Basin Specific
A21: QUESTION | B21: Is there an assured water supply at 25062 S Meridian Rd, Queen Creek, AZ 85142?
A22: ANSWER being scored | B22: I can't determine assured water supply status for a specific address. Queen Creek straddles Maricopa and Pinal counties, both covered by Arizona's AMA system, so the buyer or agent should check ADWR's Certificate/Designation of Assured Water Supply database, or ask the municipal provider whether it holds a Designation of Assured Water Supply covering this property.
A23: EVIDENCE available | B23: Currently there are eight AMAs (Prescott, Phoenix, Pinal, Tucson, Santa Cruz, Douglas, Willcox, Ranegras Plain) which are subject to regulation pursuant to the Groundwater Code.
A24: refusal_appropriateness / refusal_correct_decision | B24: The decision to answer or to decline was the right one for this question. | D24: 3
A25: refusal_appropriateness / refusal_no_overreach | B25: If it declined, it did not decline a question the evidence could have answered. | D25: 2
A26: refusal_appropriateness / refusal_helpful_redirect | B26: If it declined, it pointed somewhere useful rather than stopping flat. | D26: 1
A27: refusal_appropriateness / refusal_no_hedge_answer | B27: It did not half-answer a question it should have declined outright. | D27: 2
A29: q009 (SHOULD PARTLY DECLINE) - Address or Groundwater Basin Specific
A30: QUESTION | B30: Is there an assured water supply at 9972 Cattleman Rd. Holbrook, AZ 86025?
A31: ANSWER being scored | B31: I can't determine that for a specific address. Also, since Holbrook is outside any AMA, the correct program is "adequate," not "assured," water supply, a different ADWR determination with somewhat lighter requirements. Contact ADWR or the local water provider to check status.
A32: EVIDENCE available | B32: The Adequate Water Supply Program operates outside of the AMAs. It ensures that the water adequacy or inadequacy is disclosed in the public report provided to potential first purchasers.
A33: refusal_appropriateness / refusal_correct_decision | B33: The decision to answer or to decline was the right one for this question. | D33: 3
A34: refusal_appropriateness / refusal_no_overreach | B34: If it declined, it did not decline a question the evidence could have answered. | D34: 2
A35: refusal_appropriateness / refusal_helpful_redirect | B35: If it declined, it pointed somewhere useful rather than stopping flat. | D35: 1
A36: refusal_appropriateness / refusal_no_hedge_answer | B36: It did not half-answer a question it should have declined outright. | D36: 2
A38: q012 (SHOULD PARTLY DECLINE) - Address or Groundwater Basin Specific
A39: QUESTION | B39: Is the Agua Fria groundwater basin healthy?
A40: ANSWER being scored | B40: I can't give a single yes/no on basin health. ADWR does publish a Supply and Demand Report (SDR) for each basin, required every 5 years, but it's a basin-wide water budget, not a fine-grained groundwater flow model, so it can't confirm the situation at any one parcel. Check the current SDR for the Agua Fria basin (or the Phoenix AMA management plan, which covers it) for the actual current data rather than relying on a general answer.
A41: EVIDENCE available | B41: The SDRs are structured as water budgets, focusing on total inflows and outflows at the basin scale. The SDRs are not groundwater flow models with finer geographic results, which are conducted by ADWR's Hydrology Division.
A42: refusal_appropriateness / refusal_correct_decision | B42: The decision to answer or to decline was the right one for this question. | D42: 3
A43: refusal_appropriateness / refusal_no_overreach | B43: If it declined, it did not decline a question the evidence could have answered. | D43: 2
A44: refusal_appropriateness / refusal_helpful_redirect | B44: If it declined, it pointed somewhere useful rather than stopping flat. | D44: 1
...

Sheet Arm 3 - Rollup (auto)
A1: Item | B1: Weight earned | C1: Weight possible | D1: Share earned | E1: Arm 3 score
A2: This sheet fills itself in from Arm 2. Nothing to do here.
A3: q004 | B3: =SUMIF('Arm 2 - Checklist'!$C$7:$C$18,"Yes",'Arm 2 - Checklist'!$D$7:$D$18) | C3: =SUM('Arm 2 - Checklist'!$D$7:$D$18)-SUMIF('Arm 2 - Checklist'!$C$7:$C$18,"NA",'Arm 2 - Checklist'!$D$7:$D$18) | D3: =IF(C3=0,"",B3/C3) | E3: =IF(D3="","",IF(D3>=0.9,4,IF(D3>=0.7,3,IF(D3>=0.4,2,1))))
A4: q008 | B4: =SUMIF('Arm 2 - Checklist'!$C$24:$C$27,"Yes",'Arm 2 - Checklist'!$D$24:$D$27) | C4: =SUM('Arm 2 - Checklist'!$D$24:$D$27)-SUMIF('Arm 2 - Checklist'!$C$24:$C$27,"NA",'Arm 2 - Checklist'!$D$24:$D$27) | D4: =IF(C4=0,"",B4/C4) | E4: =IF(D4="","",IF(D4>=0.9,4,IF(D4>=0.7,3,IF(D4>=0.4,2,1))))
A5: q009 | B5: =SUMIF('Arm 2 - Checklist'!$C$33:$C$36,"Yes",'Arm 2 - Checklist'!$D$33:$D$36) | C5: =SUM('Arm 2 - Checklist'!$D$33:$D$36)-SUMIF('Arm 2 - Checklist'!$C$33:$C$36,"NA",'Arm 2 - Checklist'!$D$33:$D$36) | D5: =IF(C5=0,"",B5/C5) | E5: =IF(D5="","",IF(D5>=0.9,4,IF(D5>=0.7,3,IF(D5>=0.4,2,1))))
A6: q012 | B6: =SUMIF('Arm 2 - Checklist'!$C$42:$C$45,"Yes",'Arm 2 - Checklist'!$D$42:$D$45) | C6: =SUM('Arm 2 - Checklist'!$D$42:$D$45)-SUMIF('Arm 2 - Checklist'!$C$42:$C$45,"NA",'Arm 2 - Checklist'!$D$42:$D$45) | D6: =IF(C6=0,"",B6/C6) | E6: =IF(D6="","",IF(D6>=0.9,4,IF(D6>=0.7,3,IF(D6>=0.4,2,1))))
A7: q013 | B7: =SUMIF('Arm 2 - Checklist'!$C$51:$C$62,"Yes",'Arm 2 - Checklist'!$D$51:$D$62) | C7: =SUM('Arm 2 - Checklist'!$D$51:$D$62)-SUMIF('Arm 2 - Checklist'!$C$51:$C$62,"NA",'Arm 2 - Checklist'!$D$51:$D$62) | D7: =IF(C7=0,"",B7/C7) | E7: =IF(D7="","",IF(D7>=0.9,4,IF(D7>=0.7,3,IF(D7>=0.4,2,1))))
A8: q017 | B8: =SUMIF('Arm 2 - Checklist'!$C$68:$C$79,"Yes",'Arm 2 - Checklist'!$D$68:$D$79) | C8: =SUM('Arm 2 - Checklist'!$D$68:$D$79)-SUMIF('Arm 2 - Checklist'!$C$68:$C$79,"NA",'Arm 2 - Checklist'!$D$68:$D$79) | D8: =IF(C8=0,"",B8/C8) | E8: =IF(D8="","",IF(D8>=0.9,4,IF(D8>=0.7,3,IF(D8>=0.4,2,1))))
A9: q018 | B9: =SUMIF('Arm 2 - Checklist'!$C$85:$C$96,"Yes",'Arm 2 - Checklist'!$D$85:$D$96) | C9: =SUM('Arm 2 - Checklist'!$D$85:$D$96)-SUMIF('Arm 2 - Checklist'!$C$85:$C$96,"NA",'Arm 2 - Checklist'!$D$85:$D$96) | D9: =IF(C9=0,"",B9/C9) | E9: =IF(D9="","",IF(D9>=0.9,4,IF(D9>=0.7,3,IF(D9>=0.4,2,1))))
A10: q020 | B10: =SUMIF('Arm 2 - Checklist'!$C$102:$C$113,"Yes",'Arm 2 - Checklist'!$D$102:$D$113) | C10: =SUM('Arm 2 - Checklist'!$D$102:$D$113)-SUMIF('Arm 2 - Checklist'!$C$102:$C$113,"NA",'Arm 2 - Checklist'!$D$102:$D$113) | D10: =IF(C10=0,"",B10/C10) | E10: =IF(D10="","",IF(D10>=0.9,4,IF(D10>=0.7,3,IF(D10>=0.4,2,1))))
A11: q021 | B11: =SUMIF('Arm 2 - Checklist'!$C$119:$C$130,"Yes",'Arm 2 - Checklist'!$D$119:$D$130) | C11: =SUM('Arm 2 - Checklist'!$D$119:$D$130)-SUMIF('Arm 2 - Checklist'!$C$119:$C$130,"NA",'Arm 2 - Checklist'!$D$119:$D$130) | D11: =IF(C11=0,"",B11/C11) | E11: =IF(D11="","",IF(D11>=0.9,4,IF(D11>=0.7,3,IF(D11>=0.4,2,1))))
A12: q022 | B12: =SUMIF('Arm 2 - Checklist'!$C$136:$C$147,"Yes",'Arm 2 - Checklist'!$D$136:$D$147) | C12: =SUM('Arm 2 - Checklist'!$D$136:$D$147)-SUMIF('Arm 2 - Checklist'!$C$136:$C$147,"NA",'Arm 2 - Checklist'!$D$136:$D$147) | D12: =IF(C12=0,"",B12/C12) | E12: =IF(D12="","",IF(D12>=0.9,4,IF(D12>=0.7,3,IF(D12>=0.4,2,1))))
A13: q023 | B13: =SUMIF('Arm 2 - Checklist'!$C$153:$C$156,"Yes",'Arm 2 - Checklist'!$D$153:$D$156) | C13: =SUM('Arm 2 - Checklist'!$D$153:$D$156)-SUMIF('Arm 2 - Checklist'!$C$153:$C$156,"NA",'Arm 2 - Checklist'!$D$153:$D$156) | D13: =IF(C13=0,"",B13/C13) | E13: =IF(D13="","",IF(D13>=0.9,4,IF(D13>=0.7,3,IF(D13>=0.4,2,1))))
A14: q027 | B14: =SUMIF('Arm 2 - Checklist'!$C$162:$C$173,"Yes",'Arm 2 - Checklist'!$D$162:$D$173) | C14: =SUM('Arm 2 - Checklist'!$D$162:$D$173)-SUMIF('Arm 2 - Checklist'!$C$162:$C$173,"NA",'Arm 2 - Checklist'!$D$162:$D$173) | D14: =IF(C14=0,"",B14/C14) | E14: =IF(D14="","",IF(D14>=0.9,4,IF(D14>=0.7,3,IF(D14>=0.4,2,1))))

Sheet Anchor reference
A1: Dimension | B1: Score | C1: What that score means
A2: grounding | B2: Is every factual claim in the response supported by the retrieved evidence?
B3: 4 | C3: Every factual claim traces to a specific retrieved passage. No claims are added beyond what the evidence supports.
B4: 3 | C4: All major claims are supported. Minor uncontroversial framing (e.g. a general definition) is unsupported but does not alter the answer.
B5: 2 | C5: At least one substantive claim is unsupported by any retrieved passage, or generalises well beyond what a passage states.
B6: 1 | C6: Central claims are unsupported or contradict the retrieved passages.
A8: correctness | B8: Is the answer factually right?
B9: 4 | C9: Fully correct, including entity names, numeric values, and units.
B10: 3 | C10: Substantively correct; a peripheral detail is wrong or imprecise but the answer would not mislead a reader.
B11: 2 | C11: Contains a materially wrong entity, number, unit, or relationship that would mislead a reader acting on it.
B12: 1 | C12: The core answer is wrong, or asserts the opposite of the true position.
A14: refusal_appropriateness | B14: Did the system decline when it should have, and answer when it should have?
B15: 4 | C15: Correct decision. Out-of-scope questions are declined with a brief reason and, where possible, a useful redirect. In-scope questions are answered.
B16: 3 | C16: Correct decision, but poorly executed - declines without explanation, or answers while hedging so heavily the answer is hard to use.
B17: 2 | C17: Partially wrong decision: answers an out-of-scope question while signalling uncertainty, or refuses an in-scope question it had sufficient evidence to answer.
B18: 1 | C18: Wrong decision, confidently. Gives a substantive answer to an out-of-scope question, or flatly refuses a question the evidence clearly supports.

Sheet Time log
B1: Minutes you spent | C1: Anything that slowed you down
A2: Arm 1 - Anchored
A3: Arm 2 - Checklist
A5: Roughly is fine. We use this only to break a tie between two rubrics that agree about equally well - the faster one wins, because annotator time is our real constraint.

Sheet _meta
A1: annotator_id | B1: annotator_1
A2: n_items | B2: 12
A3: item_ids | B3: q004,q008,q009,q012,q013,q017,q018,q020,q021,q022,q023,q027
